Workbook

Sheet TOP 40
A1: Company Name | B1: PROVINCE | C1: Date of last inv | D1: CM
A2: ='route plans'!A64 -> RANJHA TRADERS HARDWARE & DIY STORE | B2: ='route plans'!D64 -> GAUTENG | C2: ='route plans'!P64 -> 0 | D2: ='route plans'!R64 -> N
A3: ='route plans'!A65 -> SINOVILLE FENCING | B3: ='route plans'!D65 -> GAUTENG | C3: ='route plans'!P65 -> 0 | D3: ='route plans'!R65 -> N
A4: ='route plans'!A66 -> TIMBERCITY ALLDAYS | B4: ='route plans'!D66 -> LIMPOPO | C4: ='route plans'!P66 -> 0 | D4: ='route plans'!R66 -> Y
A5: ='route plans'!A69 -> UNIVERSAL PAINTS MENLYN | B5: POLOKWANE | C5: ='route plans'!P69 -> 0 | D5: ='route plans'!R69 -> N
A6: ='route plans'!#REF! -> #REF! | B6: POLOKWANE | C6: ='route plans'!#REF! -> #REF! | D6: ='route plans'!#REF! -> #REF!
A7: ='route plans'!A70 -> AJ BOLTS & NUTS | B7: POLOKWANE | C7: ='route plans'!P70 -> 0 | D7: ='route plans'!R70 -> N
A8: ='route plans'!A71 -> SAZAR TILE AND HARDWARE | B8: GAUTENG | C8: ='route plans'!P71 -> 0 | D8: ='route plans'!R71 -> N
A9: ='route plans'!A12 -> RALF SUPPLIES | B9: ='route plans'!D72 -> GAUTENG | C9: ='route plans'!P72 -> 0 | D9: ='route plans'!R72 -> N
A10: ='route plans'!A73 -> MUHAMMADS HARDWARE | B10: GAUTENG | C10: ='route plans'!P73 -> 0 | D10: ='route plans'!R73 -> Y
A11: ='route plans'!A74 -> MACBUILD | B11: GAUTENG | C11: ='route plans'!P74 -> 44261 | D11: ='route plans'!R74 -> N
A12: ='route plans'!A75 -> BUCO ATHLONE | B12: ='route plans'!D75 -> WESTERN CAPE | C12: ='route plans'!P75 -> 44350 | D12: ='route plans'!R75 -> N
A13: ='route plans'!A76 -> JACKRITE MICA QUEESWOOD | B13: GAUTENG | C13: ='route plans'!P76 -> 0 | D13: ='route plans'!R76 -> N
A14: ='route plans'!A77 -> LIGHTHOUSE MICA HARDWARE | B14: GAUTENG | C14: ='route plans'!P77 -> 0 | D14: ='route plans'!R77 -> N
A15: ='route plans'!A78 -> DIY NORTHDALE | B15: ='route plans'!D78 -> GAUTENG | C15: ='route plans'!P78 -> 0 | D15: ='route plans'!R78 -> N
A16: ='route plans'!A80 -> AKSA BUILDERS SUPPLIERS | B16: GAUTENG | C16: ='route plans'!P80 -> 0 | D16: ='route plans'!R80 -> N
A17: ='route plans'!A81 -> KHAN'S HARDWARE & GENERAL DEALER | B17: ='route plans'!D81 -> GAUTENG | C17: ='route plans'!P81 -> 0 | D17: ='route plans'!R81 -> N
A18: ='route plans'!A82 -> DIY THE REEDS | B18: ='route plans'!D82 -> GAUTENG | C18: ='route plans'!P82 -> 0 | D18: ='route plans'!R82 -> N
A19: ='route plans'!A83 -> DIY LYTTLETON | B19: ='route plans'!D83 -> GAUTENG | C19: ='route plans'!P83 -> 0 | D19: ='route plans'!R83 -> N
A20: ='route plans'!A84 -> RAMODISE SUPERSTORE & WHOLESALES | B20: ='route plans'!D84 -> GAUTENG | C20: ='route plans'!P84 -> 0 | D20: ='route plans'!R84 -> N
A21: =#REF! -> #REF! | B21: =#REF! -> #REF! | C21: =#REF! -> #REF! | D21: =#REF! -> #REF!
A22: ='route plans'!A88 -> ALL PAINT & HARDWARE JEFFREY’S BAY (DAJEES ) | B22: ='route plans'!D88 -> EASTERN CAPE | C22: ='route plans'!P88 -> 0 | D22: ='route plans'!R88 -> N
A23: ='route plans'!A89 -> ALLIED BUILD (ADDITIONAL DELIVERY ADDRESS FOR INDALI) | B23: ='route plans'!D89 -> EASTERN CAPE | C23: ='route plans'!P89 -> 0 | D23: ='route plans'!R89 -> N
A24: ='route plans'!A90 -> STEEL & PIPES CENTURION | B24: ='route plans'!D90 -> GAUTENG | C24: ='route plans'!P90 -> 0 | D24: ='route plans'!R90 -> N
A25: ='route plans'!A91 -> ALLIED BUILDERS CLAYVILLE | B25: ='route plans'!D91 -> GAUTENG | C25: ='route plans'!P91 -> 0 | D25: ='route plans'!R91 -> N
A26: ='route plans'!A92 -> HAMMERKOP HARDWARE | B26: ='route plans'!D92 -> GAUTENG | C26: ='route plans'!P92 -> 0 | D26: ='route plans'!R92 -> N
A27: ='route plans'!A96 -> HUMPHRIES &JEWELL | B27: GAUTENG | C27: ='route plans'!P96 -> 0 | D27: ='route plans'!R96 -> Y
A28: ='route plans'!A97 -> NJR STEEL PTA EAST | B28: ='route plans'!D97 -> GAUTENG | C28: ='route plans'!P97 -> 0 | D28: ='route plans'!R97 -> N
A29: ='route plans'!A98 -> ALLIED BUILDERS HAMMANSKRAAL | B29: GAUTENG | C29: ='route plans'!P98 -> 0 | D29: ='route plans'!R98 -> N
A30: ='route plans'!A99 -> ALPHA BUILD HARDWARE | B30: GAUTENG | C30: ='route plans'!P99 -> 0 | D30: ='route plans'!R99 -> N
A31: =#REF! -> #REF! | B31: =#REF! -> #REF! | C31: =#REF! -> #REF! | D31: =#REF! -> #REF!
A32: ='route plans'!A100 -> WESLOU FLOOR COVERINGS | B32: ='route plans'!D100 -> LIMPOPO | C32: ='route plans'!P100 -> 0 | D32: ='route plans'!R100 -> N
A33: ='route plans'!A101 -> MILLENIUM PIPE & STEEL | B33: ='route plans'!D101 -> GAUTENG | C33: ='route plans'!P101 -> 0 | D33: ='route plans'!R101 -> N
A34: ='route plans'!A103 -> TIMBERCITY THOHOYANDOU | B34: GAUTENG | C34: ='route plans'!P103 -> 0 | D34: ='route plans'!R103 -> Y
A35: ='route plans'!A105 -> DADA'S WORLD OF HARWARE | B35: ='route plans'!D105 -> LIMPOPO | C35: ='route plans'!P105 -> 0 | D35: ='route plans'!R105 -> N
A36: ='route plans'!A106 -> ALPHA BUILDERS SUPPLY | B36: ='route plans'!D106 -> GAUTENG | C36: ='route plans'!P106 -> 0 | D36: ='route plans'!R106 -> Y
A37: ='route plans'!A108 -> VALHALLA GENERAL DEALERS | B37: GAUTENG | C37: ='route plans'!P108 -> 0 | D37: ='route plans'!R108 -> N
A38: ='route plans'!A109 -> CLUB SEVEN HARDWARE | B38: GAUTENG | C38: ='route plans'!P109 -> 0 | D38: ='route plans'!R109 -> N
A39: ='route plans'!A110 -> ALPHA BUILDERS SUPPLY | B39: ='route plans'!D110 -> GAUTENG | C39: ='route plans'!P110 -> 0 | D39: ='route plans'!R110 -> N
A40: ='route plans'!A111 -> EKAYA HARDWARE GAUTENG | B40: ='route plans'!D111 -> GAUTENG | C40: ='route plans'!P111 -> 0 | D40: ='route plans'!R111 -> Y
...

Sheet route plans
A1: STORE NAME | B1: AREA | C1: CITY | D1: PROVINCE | E1: STREET ADDRESS | F1: EMAIL | G1: WHOLESALER | H1: GROUP | I1: ACTIVE/INACTIVE | J1: DATE VISITED | K1: Days since last visted | L1: NEXT VISIT DATE | M1: PRODUCT | N1: TYPE OF CLIENT | O1: CREDIT APP | P1: Last invoice sent date | Q1: Days from last order | R1: Cornice Maker | S1: CURRENT SUPPLIER | T1: CUSTOMER NAME | U1: CUSTOMER NUMBER | V1: REP NAME | W1: CUSTOMER COMMENTS | X1: LAST PHONED DATE | Y1: DAYS FROM LAST CALL | Z1: PHONED BY | AA1: EMAIL | AB1: LAST MAILED | AC1: DAYS FROM LAST MAIL | AD1: MAILED BY | AE1: WHAT WAS MAILED | AF1: CLIENT FEEDBACK | AG1: HAPPY/ANGRY
A2: Power Build MODIMOLLE | B2: MODIMOLE | C2: MODIMOLE | D2: LIMPOPO | E2: CORNER OF NELSON MANDELA AND ALLAN STREET, MODIMOLLE, 0150 | G2: NO | H2: POWER BUILD | I2: ACTIVE | J2: 44572 | K2: =ABS(IF(ISBLANK(J2),"",TODAY()-J2)) -> 735 | L2: =J2+14 -> 44586 | M2: CORNICE | N2: N/A | O2: NO | Q2: =ABS(IF(ISBLANK(P2),"",TODAY()-P2)) -> #VALUE! | R2: N | T2: VAN ZYL OBERHOLZER | U2: 084 417 2334 | V2: TYRONE | W2: CLIENT ACCEPTED QUOTE, WILL SEND DOCUMENTS FOR APPROVAL | X2: 44480 | Y2: 9 | Z2: YOLANDI | AA2: VANZYLOBE@GMAIL.COM | AB2: 44508 | AC2: =ABS(IF(ISBLANK(AB2),"",TODAY()-AB2)) -> 799 | AD2: YOLANDI | AE2: POWER BUILD BR PROMOTION | AF2: CLIENT WILL COMPLETE CREDIT APP
A3: Power Build THLABANE | B3: THLABANE | C3: RUSTENBURG | D3: NORTH WEST | E3: 219 BEYERS NAUDE, RUSTENBURG, NORTHWEST, 0299 | G3: NO | H3: POWER BUILD | I3: INACTIVE | J3: 44378 | K3: =ABS(IF(ISBLANK(J3),"",TODAY()-J3)) -> 929 | L3: =J3+14 -> 44392 | M3: CORNICE | N3: N/A | O3: NO | Q3: =ABS(IF(ISBLANK(P3),"",TODAY()-P3)) -> #VALUE! | R3: N | T3: JOHN | U3: 824801380 | V3: HEYNS | Y3: 44489 | AA3: MSIZI@RTINDUSTRIES.CO.ZA | AB3: 44480 | AC3: =ABS(IF(ISBLANK(AB3),"",TODAY()-AB3)) -> 827 | AD3: YOLANDI | AE3: POWER BUILD BR PROMOTION
A4: MAKRO CROWN MINES | B4: SELBY | C4: SELBY | D4: GAUTENG | E4: CORNER OF MAIN REEF ROAD & HANOVER STREET, SELBY, JHB | G4: NO | H4: MAKRO | I4: ACTIVE | J4: 44585 | K4: =ABS(IF(ISBLANK(J4),"",TODAY()-J4)) -> 722 | L4: =J4+14 -> 44599 | M4: GRASS/PEBBLES/POTS | N4: N/A | O4: NO | R4: N | S4: FLINSTONE | V4: ELSA
A5: HDS CUT & EDGE | B5: BENONI | C5: BENONI | D5: GAUTENG | E5: 28 Liverpool Road, Benoni | G5: NO | H5: CUT & EDGE | I5: NEW | J5: 44579 | K5: =ABS(IF(ISBLANK(J5),"",TODAY()-J5)) -> 728 | L5: =J5+14 -> 44593 | M5: CORNICE | N5: N/A | O5: NO | Q5: =ABS(IF(ISBLANK(P5),"",TODAY()-P5)) -> #VALUE! | R5: N | T5: Zack | U5: 011 422 4839 | V5: REINHARDT | W5: Appointment to be scheduled for the 1st week of September | X5: 44473 | Y5: 16 | Z5: YOLANDI | AA5: SALES@HDSVANDERBIJLPARK.CO.ZA | AB5: 44497 | AC5: =ABS(IF(ISBLANK(AB5),"",TODAY()-AB5)) -> 810 | AD5: YOLANDI | AE5: HOMEPACK BR PROMOTION
A6: TLT INDUSTRIAL HARDWARE SUPPLIES | B6: KEMPTON PARK | C6: KEMPTON PARK | D6: GAUTENG | E6: 49 rRIGGER ROAD, SPARTAN, KEMPTON | G6: NO | H6: ESSENTIAL | I6: NEW | J6: 44588 | K6: =ABS(IF(ISBLANK(J6),"",TODAY()-J6)) -> 719 | L6: =J6+14 -> 44602 | M6: CORNICE | N6: N/A | O6: NO | R6: N | T6: Leigh-Anne | U6: 011 394 9689 | V6: REINHARDT | W6: Callback after 13:00
A7: MAKRO ALBERTON | B7: ALBERTON | C7: ALBERTON | D7: GAUTENG | E7: CORNER OF HEIDELBERG ROAD & ASCOT ROAD, NEWMARKET, ALBERTON | G7: NO | H7: MAKRO | I7: ACTIVE | J7: 12/10/0221 | K7: =ABS(IF(ISBLANK(J7),"",TODAY()-J7)) -> #VALUE! | L7: =J7+14 -> #VALUE! | M7: GRASS/PEBBLES/POTS
A8: DIE HOUT FABRIEK | B8: VAN DER BIJL | C8: VAN DER BIJL | D8: GAUTENG | E8: 3 WEBBER STR | G8: NO | H8: NONE | I8: INACTIVE | J8: 44420 | K8: =ABS(IF(ISBLANK(J8),"",TODAY()-J8)) -> 887 | L8: =J8+14 -> 44434 | M8: CORNICE | N8: N/A | O8: NO | P8: 44376 | Q8: =ABS(IF(ISBLANK(P8),"",TODAY()-P8)) -> 931 | R8: N | U8: 0169337712 | V8: HEYNS | X8: 44473 | Y8: 16 | Z8: YOLANDI | AA8: DIEHOUTFABRIEK@VODAMAIL.CO.ZA | AB8: 44497 | AC8: =ABS(IF(ISBLANK(AB8),"",TODAY()-AB8)) -> 810 | AD8: YOLANDI | AE8: HOMEPACK BR PROMOTION
A9: STYLISH CEILINGS SPRINGS | B9: SPRINGS | C9: SPRINGS | D9: GAUTENG | E9: 208 NIGEL ROAD, SPRINGS | G9: NO | H9: NONE | I9: NEW | J9: 44579 | K9: =ABS(IF(ISBLANK(J9),"",TODAY()-J9)) -> 728 | L9: =J9+14 -> 44593 | M9: CORNICE | N9: N/A | O9: N | R9: N | T9: COLE KUKKARD/JP | U9: 064 843 9138 | V9: REINHARDT | W9: Callback after 14:00
A10: MAKRO CARNIVAL | B10: BOKSBURG | C10: BOKSBURG | D10: GAUTENG | E10: 16 BEECHWOOD STREET, BRAKPAN | G10: NO | H10: MAKRO | I10: ACTIVE | J10: 44585 | K10: =ABS(IF(ISBLANK(J10),"",TODAY()-J10)) -> 722 | L10: =J10+14 -> 44599 | M10: GRASS/PEBBLES/POTS | N10: N/A | O10: N | Q10: =ABS(IF(ISBLANK(P10),"",TODAY()-P10)) -> #VALUE! | R10: N | S10: FLINSTONE | V10: ELSA
A11: MAKRO GERMISTON | B11: GERMISTON | C11: GERMISTON | D11: GAUTENG | E11: 16 HERMAN STREET, MEADOWDALE, GERMISTON | G11: NO | H11: MAKRO | I11: ACTIVE | J11: 44585 | K11: =ABS(IF(ISBLANK(J11),"",TODAY()-J11)) -> 722 | L11: =J11+14 -> 44599 | M11: GRASS/PEBBLES/POTS | N11: N/A | O11: N | Q11: =ABS(IF(ISBLANK(P11),"",TODAY()-P11)) -> #VALUE! | R11: N | S11: FLINSTONE | V11: ELSA | W11: NEEDS STANDS
A12: RALF SUPPLIES | B12: VAN DER BIJL | C12: VAN DER BIJL | D12: GAUTENG | E12: 10 NORTH ST | G12: NO | H12: NONE | I12: INACTIVE | J12: 44417 | K12: =ABS(IF(ISBLANK(J12),"",TODAY()-J12)) -> 890 | L12: =J12+14 -> 44431 | M12: CORNICE | N12: N/A | O12: NO | Q12: =ABS(IF(ISBLANK(P12),"",TODAY()-P12)) -> #VALUE! | R12: N | U12: 0169324060 | V12: HEYNS | X12: 44473 | Y12: 16 | Z12: YOLANDI | AA12: RALF@ADMIN@LANTIC.NET | AB12: 44497 | AC12: =ABS(IF(ISBLANK(AB12),"",TODAY()-AB12)) -> 810 | AD12: YOLANDI | AE12: HOMEPACK BR PROMOTION
A13: AK'S DISTRIBUTORS T/A DAWSONS HARDWARE | B13: LYDENBURG | C13: LYDENBURG | D13: MPUMALANGA | E13: 38 JOUBERT STREET, LYDENBURG | G13: NO | H13: NONE | I13: NEW | J13: 44599 | K13: =ABS(IF(ISBLANK(J13),"",TODAY()-J13)) -> 708 | L13: =J13+14 -> 44613 | M13: CORNICE | N13: N/A | O13: NO | Q13: =ABS(IF(ISBLANK(P13),"",TODAY()-P13)) -> #VALUE! | R13: N | T13: ABDUL | U13: 0728676302 | V13: REINHARDT | W13: ORDERED
A14: KLIPKOR | B14: VAN DER BIJL | C14: VAN DER BIJL | D14: GAUTENG | E14: EASTMAN STREET | G14: NO | H14: NONE | I14: INACTIVE | J14: 44414 | K14: =ABS(IF(ISBLANK(J14),"",TODAY()-J14)) -> 893 | L14: =J14+14 -> 44428 | M14: CORNICE | N14: N/A | O14: NO | Q14: =ABS(IF(ISBLANK(P14),"",TODAY()-P14)) -> #VALUE! | R14: N | U14: 0169861441 | V14: HEYNS | X14: 44473 | Y14: 16 | Z14: YOLANDI | AA14: KLIPKOR@ABSAMAIL.CO.ZA | AB14: 44497 | AC14: =ABS(IF(ISBLANK(AB14),"",TODAY()-AB14)) -> 810 | AD14: YOLANDI | AE14: HOMEPACK BR PROMOTION
A15: BUILDERS CORNER | B15: BENONI | C15: BENONI | D15: GAUTENG | E15: 36 SWAN STREET, BENONI | G15: NO | H15: NONE | I15: NEW | J15: 44585 | K15: =ABS(IF(ISBLANK(J15),"",TODAY()-J15)) -> 722 | L15: =J15+14 -> 44599 | M15: CORNICE | N15: N/A | O15: N | Q15: =ABS(IF(ISBLANK(P15),"",TODAY()-P15)) -> #VALUE! | R15: N | S15: ELEGANT | T15: NAHEEM | U15: 011 421 0011/065 320 6505 | V15: REINHARDT | W15: Catalogue sent, to follow-up tomorrow
A16: IMPACT | B16: VAN DER BIJL | C16: VAN DER BIJL | D16: GAUTENG | E16: GOLDEN HIGH WAY | G16: NO | H16: NONE | I16: INACTIVE | J16: 44409 | K16: =ABS(IF(ISBLANK(J16),"",TODAY()-J16)) -> 898 | L16: =J16+14 -> 44423 | M16: CORNICE | N16: N/A | O16: NO | Q16: =ABS(IF(ISBLANK(P16),"",TODAY()-P16)) -> #VALUE! | R16: N | U16: 0795007917 | V16: HEYNS | X16: 44473 | Y16: 16 | Z16: YOLANDI | AA16: BUYER@BOLTANDNUT.CO.ZA | AB16: 44497 | AC16: =ABS(IF(ISBLANK(AB16),"",TODAY()-AB16)) -> 810 | AD16: YOLANDI | AE16: HOMEPACK BR PROMOTION
A17: OLYMPIC MICA | B17: VAN DER BIJL | C17: VAN DER BIJL | D17: GAUTENG | E17: 2 PETTER ST | G17: NO | H17: MICA | I17: INACTIVE | J17: 44405 | K17: =ABS(IF(ISBLANK(J17),"",TODAY()-J17)) -> 902 | L17: =J17+14 -> 44419 | M17: CORNICE | N17: N/A | O17: NO | Q17: =ABS(IF(ISBLANK(P17),"",TODAY()-P17)) -> #VALUE! | R17: N | U17: 0169819135 | V17: HEYNS | X17: 44473 | Y17: 16 | Z17: YOLANDI | AA17: INFO@OLYMPICMICA.CO.ZA | AB17: 44497 | AC17: =ABS(IF(ISBLANK(AB17),"",TODAY()-AB17)) -> 810 | AD17: YOLANDI | AE17: HOMEPACK BR PROMOTION
A18: CONSTRUCTA | B18: VAN DER BIJL | C18: VAN DER BIJL | D18: GAUTENG | E18: CNR RAUTENBACH,GOLDEN | G18: NO | H18: NONE | I18: NEW | J18: 44578 | K18: =ABS(IF(ISBLANK(J18),"",TODAY()-J18)) -> 729 | L18: =J18+14 -> 44592 | M18: CORNICE | N18: N/A | O18: NO | Q18: =ABS(IF(ISBLANK(P18),"",TODAY()-P18)) -> #VALUE! | R18: N | T18: WEAN | U18: 0161100181 | V18: ELSA | W18: SPOKE TO DEAN, STARTING A HOUSING DEVELOPMENT IN FEB, MUST SEE HIM AGAIN IN FEB | X18: 44473 | Y18: 16 | Z18: YOLANDI | AA18: WEAN@CONSTRUCTA.COM | AB18: 44497 | AC18: =ABS(IF(ISBLANK(AB18),"",TODAY()-AB18)) -> 810 | AD18: YOLANDI | AE18: HOMEPACK BR PROMOTION
A19: CARRIGTON HARDWARE ATHLONE | B19: ATHLONE | C19: ATHLONE | D19: WESTERN CAPE | E19: ATHLONE | G19: NO | H19: NONE | I19: ACTIVE | J19: 44434 | K19: =ABS(IF(ISBLANK(J19),"",TODAY()-J19)) -> 873 | L19: =J19+14 -> 44448 | M19: CORNICE | N19: COD | O19: N | Q19: =ABS(IF(ISBLANK(P19),"",TODAY()-P19)) -> #VALUE! | R19: N | X19: 44487 | Y19: 2 | Z19: YOLANDI | AA19: FOXBOUERS@TELKOMSA.NET | AB19: 44497 | AC19: =ABS(IF(ISBLANK(AB19),"",TODAY()-AB19)) -> 810 | AD19: YOLANDI | AE19: HOMEPACK BR PROMOTION
A20: JACKS | B20: VAN DER BIJL | C20: VAN DER BIJL | D20: GAUTENG | E20: 2 PETTER ST VAN DER BIJL | G20: NO | H20: NONE | I20: INACTIVE | J20: 44397 | K20: =ABS(IF(ISBLANK(J20),"",TODAY()-J20)) -> 910 | L20: =J20+14 -> 44411 | M20: CORNICE | N20: N/A | O20: NO | Q20: =ABS(IF(ISBLANK(P20),"",TODAY()-P20)) -> #VALUE! | R20: N | U20: 0169819135 | V20: HEYNS | X20: 44473 | Y20: 16 | Z20: YOLANDI | AA20: INFO@OLYMPICMICA.CO.ZA | AB20: 44497 | AC20: =ABS(IF(ISBLANK(AB20),"",TODAY()-AB20)) -> 810 | AD20: YOLANDI | AE20: HOMEPACK BR PROMOTION
A21: TUGELA | B21: VAN DER BIJL | C21: VAN DER BIJL | D21: GAUTENG | E21: 134 HANS STRYDOM | G21: NO | H21: NONE | I21: INACTIVE | J21: 44582 | K21: =ABS(IF(ISBLANK(J21),"",TODAY()-J21)) -> 725 | L21: =J21+14 -> 44596 | M21: CORNICE | N21: N/A | O21: NO | Q21: =ABS(IF(ISBLANK(P21),"",TODAY()-P21)) -> #VALUE! | R21: N | S21: ELEGANT | T21: NITA | U21: 0169816900 | V21: REINHARDT | W21: WILL COMPARE PRICE | X21: 44473 | Y21: 16 | Z21: YOLANDI | AA21: TUGELA.ORDERS@CYBERSERVE.CO.ZA | AB21: 44497 | AC21: =ABS(IF(ISBLANK(AB21),"",TODAY()-AB21)) -> 810 | AD21: YOLANDI | AE21: HOMEPACK BR PROMOTION
A22: MAKRO CENTURION | B22: CENTURION | C22: CENTURION | D22: GAUTENG | E22: 2 BLOUKRANS ROAD, CENTURION | G22: NO | H22: MAKRO | I22: ACTIVE | J22: 44582 | K22: =ABS(IF(ISBLANK(J22),"",TODAY()-J22)) -> 725 | L22: =J22+14 -> 44596 | M22: GRASS | N22: N/A | O22: N | Q22: =ABS(IF(ISBLANK(P22),"",TODAY()-P22)) -> #VALUE! | R22: N | S22: FLINSTONE | V22: ELSA | W22: HAPPY
A23: 3 STAR HARDWARE BUILDING MATERIAL | B23: RELETO SECTION | C23: SILVERKRANS | D23: NORTH WEST | E23: 1435 RALETO SECTION, SILVERKRANS, NORTH WEST | G23: NO | H23: EST | I23: NEW | J23: 44386 | K23: =ABS(IF(ISBLANK(J23),"",TODAY()-J23)) -> 921 | L23: =J23+14 -> 44400 | M23: CORNICE | N23: N/A | O23: NO | Q23: =ABS(IF(ISBLANK(P23),"",TODAY()-P23)) -> #VALUE! | R23: N | T23: M.W. ARSHAD | U23: 074 518 2972 | W23: No Answer, call keeps cutting | AA23: ALI.KHATANA07@GMAIL.COM | AB23: 44497 | AC23: =ABS(IF(ISBLANK(AB23),"",TODAY()-AB23)) -> 810 | AD23: YOLANDI | AE23: HOMEPACK BR PROMOTION
A24: BUCO ATHLONE | B24: ATHLONE | C24: ATHLONE | D24: WESTERN CAPE | E24: 57 BELGRAVIA ROAD, ATHLONE, 7764 | H24: BUCO | I24: NEW | J24: 44386 | K24: =ABS(IF(ISBLANK(J24),"",TODAY()-J24)) -> 921 | L24: =J24+14 -> 44400 | M24: CORNICE | N24: N/A | O24: NO | Q24: =ABS(IF(ISBLANK(P24),"",TODAY()-P24)) -> #VALUE! | R24: N | T24: ANEESA VAN DER FORT AVANDERFORT@BUCO.CO.ZA 083 381 2597 | X24: 44487 | Y24: 2 | Z24: YOLANDI | AA24: JANNIE@AHM.CO.ZA | AB24: 44497 | AC24: =ABS(IF(ISBLANK(AB24),"",TODAY()-AB24)) -> 810 | AD24: YOLANDI | AE24: HOMEPACK BR PROMOTION | AG24: HAPPY
A25: HOT POT | B25: VEREENIGING | C25: VEREENIGING | D25: GAUTENG | E25: 108A Houtkop Road, Duncanville, Vereeniging | G25: NO | H25: NONE | I25: INACTIVE | J25: 44592 | K25: =ABS(IF(ISBLANK(J25),"",TODAY()-J25)) -> 715 | L25: =J25+14 -> 44606 | M25: CORNICE | N25: N/A | O25: NO | Q25: =ABS(IF(ISBLANK(P25),"",TODAY()-P25)) -> #VALUE! | R25: N | T25: CORLIA | U25: 0164281113 | V25: REINHARDT | W25: Requested catalogue and appointment for the week of 18th or 25th July | X25: 44473 | Y25: 16 | Z25: YOLANDI | AA25: CORLIA@HOTPOTPAINT.COM | AB25: 44497 | AC25: =ABS(IF(ISBLANK(AB25),"",TODAY()-AB25)) -> 810 | AD25: YOLANDI | AE25: HOMEPACK BR PROMOTION
A26: HARDWARE INC | B26: VEREENIGING | C26: VEREENIGING | D26: GAUTENG | E26: 1 UNION ST | G26: NO | H26: ESSENTIAL | I26: INACTIVE | J26: 44582 | K26: =ABS(IF(ISBLANK(J26),"",TODAY()-J26)) -> 725 | L26: =J26+14 -> 44596 | M26: CORNICE | N26: N/A | O26: NO | P26: 44021 | Q26: =ABS(IF(ISBLANK(P26),"",TODAY()-P26)) -> 1286 | R26: N | S26: UPPER EDGE | T26: KEVIN | U26: 0663334324 | V26: REINHARDT | W26: Callback later | X26: 44473 | Y26: 16 | Z26: YOLANDI | AA26: INAM@HARDWAREINC.CO.ZA | AB26: 44497 | AC26: =ABS(IF(ISBLANK(AB26),"",TODAY()-AB26)) -> 810 | AD26: YOLANDI | AE26: HOMEPACK BR PROMOTION
A27: A.A BUILDING MATERIAL LESOTHO | B27: LERIBE | C27: LERIBE | D27: LESOTHO | E27: AIRPORT ROAD LERIBE LESOTHO | G27: NO | H27: EST | I27: NEW | J27: 44387 | K27: =ABS(IF(ISBLANK(J27),"",TODAY()-J27)) -> 920 | L27: =J27+14 -> 44401 | M27: CORNICE | N27: N/A | O27: NO | Q27: =ABS(IF(ISBLANK(P27),"",TODAY()-P27)) -> #VALUE! | R27: N | T27: HASSEN NOORMOHAMED | U27: 266 22400795 | W27: Invalid contact details | AA27: IRSHU7860@HOTMAIL.COM | AB27: 44497 | AC27: =ABS(IF(ISBLANK(AB27),"",TODAY()-AB27)) -> 810 | AD27: YOLANDI | AE27: HOMEPACK BR PROMOTION
A28: MUNAZA TRADERS CC T/A RAJA WHOLESALERS | B28: ACORNHOEK | C28: ACORNHOEK | D28: MPUMALANGA | E28: R40 NORTH | G28: YES | H28: NONE | I28: INACTIVE | J28: 44595 | K28: =ABS(IF(ISBLANK(J28),"",TODAY()-J28)) -> 712 | L28: =J28+14 -> 44609 | M28: CORNICE | N28: 30DAYS | O28: NO | P28: 44188 | Q28: =ABS(IF(ISBLANK(P28),"",TODAY()-P28)) -> 1119 | R28: Y | T28: FIAYAZ | U28: 013 795 5297/081 248 0393 | V28: REINHARDT | W28: No Answer | AA28: ACTIONBUILD@LIVE.CO.ZA | AB28: 44497 | AC28: =ABS(IF(ISBLANK(AB28),"",TODAY()-AB28)) -> 810 | AD28: YOLANDI | AE28: HOMEPACK BR PROMOTION
A29: ACTIVE BUILD AND DÉCOR | B29: THOHOYANDOU | C29: THOHOYANDOU | D29: LIMPOPO | E29: SHOP D1B, SABINA PLAZA, THOHOYANDOU | G29: NO | H29: EST | I29: NEW | J29: 44373 | K29: =ABS(IF(ISBLANK(J29),"",TODAY()-J29)) -> 934 | L29: =J29+14 -> 44387 | M29: CORNICE | N29: N/A | O29: NO | Q29: =ABS(IF(ISBLANK(P29),"",TODAY()-P29)) -> #VALUE! | R29: N | T29: MUAAZ SAGIR | U29: 015 962 5654/072 952 4091 | W29: No Answer | AA29: ACTIVEBUILD1931@GMAIL.COM; BRIDGEMOTORS@TISCALI.CO.ZA | AB29: 44497 | AC29: =ABS(IF(ISBLANK(AB29),"",TODAY()-AB29)) -> 810 | AD29: YOLANDI | AE29: HOMEPACK BR PROMOTION
A30: BUILD IT DTM | B30: BENONI | C30: BENONI | D30: GAUTENG | E30: 19 LIVERPOOL ROAD, BENONI | G30: NO | H30: BUILD IT | I30: NEW | J30: 44579 | K30: =ABS(IF(ISBLANK(J30),"",TODAY()-J30)) -> 728 | L30: =J30+14 -> 44593 | M30: CORNICE | N30: N/A | O30: N | R30: N | S30: ELEGANT | T30: Aqeefah | U30: 011 421 7659/067 747 6933 | V30: REINHARD | W30: Requested updated catalogue via whatsapp
A31: CARRINGTON HARDWARE | B31: CAPE TOWN | C31: CAPE TOWN | D31: WESTERN CAPE | E31: 4 HAJDI CRES | G31: NO | H31: NONE | I31: ACTIVE | J31: 44603 | K31: =ABS(IF(ISBLANK(J31),"",TODAY()-J31)) -> 704 | L31: =J31+14 -> 44617 | M31: CORNICE | N31: N/A | O31: N | R31: N | V31: ASH | W31: ORDER PLACED
A32: THE FX GROUP | B32: BENONI | C32: BENONI | D32: GAUTENG | E32: 28 LIVERPOOL ROAD | G32: YES | H32: NONE | I32: NEW | J32: 44579 | K32: =ABS(IF(ISBLANK(J32),"",TODAY()-J32)) -> 728 | L32: =J32+14 -> 44593 | M32: CORNICE | N32: N/A | O32: N | R32: N | T32: ZACK | V32: REINHARD | W32: NEED TO MAKE APOINTMENT TO SEE THE BUYER
A33: ACTIVE BUILD HARDWARE | B33: OBERHOLZER | C33: CARLTONVILLE | D33: GAUTENG | E33: 44 VAN ZYL STREET, OBERHOLZER, CARLTONVILLE | G33: NO | H33: EST | I33: NEW | J33: 44372 | K33: =ABS(IF(ISBLANK(J33),"",TODAY()-J33)) -> 935 | L33: =J33+14 -> 44386 | M33: CORNICE | N33: N/A | O33: NO | Q33: =ABS(IF(ISBLANK(P33),"",TODAY()-P33)) -> #VALUE! | R33: N | T33: ZAAKIR ESSOOP | U33: 018 788 2275 | AA33: ACTIVEBUILD@GMAIL.COM | AB33: 44497 | AC33: =ABS(IF(ISBLANK(AB33),"",TODAY()-AB33)) -> 810 | AD33: YOLANDI | AE33: HOMEPACK BR PROMOTION
A34: TIMBERCITY LOUIS TRICHARDT | B34: TRICHARDT | C34: TRICHARDT | D34: LIMPOPO | E34: 93 GROBLER ST | G34: NO | H34: EST | I34: ACTIVE | J34: 44526 | K34: =ABS(IF(ISBLANK(J34),"",TODAY()-J34)) -> 781 | L34: =J34+14 -> 44540 | M34: CORNICE | N34: 30DAYS | O34: NO | Q34: =ABS(IF(ISBLANK(P34),"",TODAY()-P34)) -> #VALUE! | R34: Y | T34: MAZHAR | U34: 0820441200 | V34: TYRONE | W34: HAS ENOUGH CORNICE AND BUYS GARAGEDOORS AT THE SAME SUPPLIER AS US | X34: 44433 | Y34: 56 | AA34: BUYER@JURIHARDWARE.CO.ZA | AB34: 44497 | AC34: =ABS(IF(ISBLANK(AB34),"",TODAY()-AB34)) -> 810 | AD34: YOLANDI | AE34: HOMEPACK BR PROMOTION | AG34: HAPPY
A35: BUCO ACORNHOEK | B35: ACORNHOEK | C35: ACORNHOEK | D35: MPUMALANGA | E35: CNR R40 & GREENVALLEY TURN-OFF, GREENVALLEY TRUST FARM 473, ACORNHOEK, 1380 | G35: NO | H35: BUCO | I35: NEW | J35: 44384 | K35: =ABS(IF(ISBLANK(J35),"",TODAY()-J35)) -> 923 | L35: =J35+14 -> 44398 | M35: CORNICE | N35: N/A | O35: NO | P35: 44211 | Q35: =ABS(IF(ISBLANK(P35),"",TODAY()-P35)) -> 1096 | R35: N | T35: DEBBY GUNN-HENDERSON DGUNN-HENDERSON@BUCO.CO.ZA 073 335 7706 | X35: 44543 | Y35: 44489 | Z35: GERHARD | AA35: DWH51214@GMAIL.COM | AB35: 44497 | AC35: =ABS(IF(ISBLANK(AB35),"",TODAY()-AB35)) -> 810 | AD35: YOLANDI | AE35: HOMEPACK BR PROMOTION | AG35: HAPPY
A36: AFRI BUILD | B36: MATATIELE | C36: MATATIELE | D36: EASTERN CAPE | E36: 40 WEST ST | G36: NO | H36: NONE | I36: ACTIVE | J36: 44391 | K36: =ABS(IF(ISBLANK(J36),"",TODAY()-J36)) -> 916 | L36: =J36+14 -> 44405 | M36: CORNICE PREMIX | N36: 30DAYS | O36: NO | Q36: =ABS(IF(ISBLANK(P36),"",TODAY()-P36)) -> #VALUE! | R36: Y | S36: C/M | T36: Jolene | U36: 039 737 3163 | V36: GERHARD | Y36: 44489 | AA36: SALES@AFRIBUILD.CO.ZA | AB36: 44497 | AC36: =ABS(IF(ISBLANK(AB36),"",TODAY()-AB36)) -> 810 | AD36: YOLANDI | AE36: HOMEPACK BR PROMOTION | AG36: HAPPY
A37: AFRICAN HARDWARE BERLIN | B37: BERLIN | C37: BERLIN | D37: EASTERN CAPE | E37: 1800 LEGION STREET, BERLIN, EAST LONDON, EASTERN CAPE | G37: NO | H37: POWER BUILD | I37: INACTIVE | J37: 44387 | K37: =ABS(IF(ISBLANK(J37),"",TODAY()-J37)) -> 920 | L37: =J37+14 -> 44401 | M37: CORNICE | N37: N/A | O37: NO | P37: 44084 | Q37: =ABS(IF(ISBLANK(P37),"",TODAY()-P37)) -> 1223 | R37: N | T37: MEHDI HASSAN | U37: 081 387 6993/043 685 2019 | V37: HEYNS | Y37: 44489 | AA37: MEHDIHASSAN136@GMAIL.COM | AB37: 44480 | AC37: =ABS(IF(ISBLANK(AB37),"",TODAY()-AB37)) -> 827 | AD37: YOLANDI | AE37: POWER BUILD BR PROMOTION
A38: HONEST ELECTRICAL AND PLUMBING PTY LTD | B38: MALAMULELE | C38: MALAMULELE | D38: POLOKWANE | E38: R81 MALAMULELE | G38: NO | H38: NONE | I38: ACTIVE | J38: 44551 | K38: =ABS(IF(ISBLANK(J38),"",TODAY()-J38)) -> 756 | L38: =J38+14 -> 44565 | M38: CORNICE | N38: 30DAYS | O38: NO | P38: 44064 | Q38: =ABS(IF(ISBLANK(P38),"",TODAY()-P38)) -> 1243 | R38: N | T38: HONEST | U38: 0747912495 | V38: TYRONE | W38: BUING FROM MR BUILD, NEEDS PRICING FOR B24 & B22, & DADO FLOWER SOFT | X38: 44434 | Y38: 55 | AA38: HONESTFACTORYPRISE@GMAIL.COM | AB38: 44497 | AC38: =ABS(IF(ISBLANK(AB38),"",TODAY()-AB38)) -> 810 | AD38: YOLANDI | AE38: HOMEPACK BR PROMOTION
A39: SI HARDWARE | B39: THOHOYANDOU | C39: THOHOYANDOU | D39: LIMPOPO | E39: 2010 GARDEN STREET | G39: NO | H39: NONE | I39: ACTIVE | J39: 44550 | K39: =ABS(IF(ISBLANK(J39),"",TODAY()-J39)) -> 757 | L39: =J39+14 -> 44564 | M39: CORNICE | N39: 30DAYS | O39: NO | P39: 44400 | Q39: =ABS(IF(ISBLANK(P39),"",TODAY()-P39)) -> 907 | R39: Y | T39: NAEEM | U39: 0155900497 | V39: TYRONE | W39: WAITED FOR HES ORDER BUT GOT IT | X39: 44433 | Y39: 56 | AA39: ORDERS@SIHARDWARE.CO.ZA | AB39: 44497 | AC39: =ABS(IF(ISBLANK(AB39),"",TODAY()-AB39)) -> 810 | AD39: YOLANDI | AE39: HOMEPACK BR PROMOTION
A40: MIDRAND HYPER HARDWARE (PTY) LTD | B40: MIDRAND | C40: JOHANNESBURG | D40: GAUTENG | E40: 89 DALE RD, GLEN AUSTIN AH | G40: NO | H40: EST | I40: ACTIVE | J40: 44588 | K40: =ABS(IF(ISBLANK(J40),"",TODAY()-J40)) -> 719 | L40: =J40+14 -> 44602 | M40: PREMIX | N40: 30DAYS | O40: NO | P40: 44306 | Q40: =ABS(IF(ISBLANK(P40),"",TODAY()-P40)) -> 1001 | R40: N | T40: SALMAN | U40: 0114864000 | V40: REINHARDT | W40: WAITING FOR STANDS | X40: 44383 | Y40: 106 | AA40: SBV@SBVGROUP.CO.ZA | AB40: 44497 | AC40: =ABS(IF(ISBLANK(AB40),"",TODAY()-AB40)) -> 810 | AD40: YOLANDI | AE40: HOMEPACK BR PROMOTION
...

Sheet Complete sheet
A1: STORE NAME | B1: AREA | C1: CITY | D1: PROVINCE | E1: STREET ADDRESS | F1: WHOLESALER | G1: GROUP | H1: ACTIVE/INACTIVE | I1: DATE VISITED | J1: Days since last visted | K1: NEXT VISIT DATE | L1: Product | M1: TYPE OF CLIENT | N1: CREDIT APP | O1: Last invoice sent date | P1: Days from last order | Q1: Cornice Maker | R1: CURRENT SUPPLIER | S1: CUSTOMER NAME | T1: CUSTOMER NUMBER | U1: REP NAME | V1: CUSTOMER COMMENTS | W1: LAST PHONED DATE | X1: DAYS FROM LAST CALL | Y1: PHONED BY | Z1: EMAIL | AA1: LAST MAILED | AB1: DAYS FROM LAST MAIL | AC1: MAILED BY | AD1: WHAT WAS MAILED | AE1: CLIENT FEEDBACK | AF1: HAPPY/ANGRY | AG1: LAST MAIL DATE
A2: More Plus Paints | B2: Bloemfontein | C2: Bloemfontein | D2: Free State | E2: 3 Oranje Street Hilton Bloemfontein | G2: EST | L2: HARDWARE | S2: Johanna | T2: 051 447 5050 | Z2: megapaints@live.co.ca;boodskapvirjou@hotmail.com
A3: =UPPER('route plans'!A1419) -> 2 ACRE HARDWARE / FOX BOUERS | B3: =UPPER('route plans'!B1419) -> PIKETBERG | C3: =UPPER('route plans'!C1419) -> PIKETBERG | D3: =UPPER('route plans'!D1419) -> WESTERN CAPE | E3: =UPPER('route plans'!E1419) -> 53 LANE STREET PIKETBERG 7320 | F3: =UPPER('route plans'!G1419) -> NO | G3: =UPPER('route plans'!H1419) -> EST | L3: HARDWARE | M3: =UPPER('route plans'!N1419) -> N/A | N3: =UPPER('route plans'!O1419) -> NO | S3: =UPPER('route plans'!T1419) -> CARLO HENDRIKS | T3: ='route plans'!U1419 -> 022 91 33940 | W3: ='route plans'!X1419 -> 0 | X3: ='route plans'!Y1419 -> 0 | Y3: =UPPER('route plans'!Z1419) | Z3: =UPPER('route plans'!AA1419) -> FLOUW@TAGRI.CO.ZA | AB3: ='route plans'!AC1419 -> #VALUE!
A4: =UPPER('route plans'!A23) -> 3 STAR HARDWARE BUILDING MATERIAL | B4: =UPPER('route plans'!B23) -> RELETO SECTION | C4: =UPPER('route plans'!C23) -> SILVERKRANS | D4: =UPPER('route plans'!D23) -> NORTH WEST | E4: =UPPER('route plans'!E23) -> 1435 RALETO SECTION, SILVERKRANS, NORTH WEST | F4: =UPPER('route plans'!G23) -> NO | G4: =UPPER('route plans'!H23) -> EST | L4: HARDWARE | M4: =UPPER('route plans'!N23) -> N/A | N4: =UPPER('route plans'!O23) -> NO | S4: =UPPER('route plans'!T23) -> M.W. ARSHAD | T4: ='route plans'!U23 -> 074 518 2972 | W4: ='route plans'!X23 -> 0 | X4: ='route plans'!Y23 -> 0 | Y4: =UPPER('route plans'!Z23) | Z4: =UPPER('route plans'!AA23) -> ALI.KHATANA07@GMAIL.COM | AB4: ='route plans'!AC23 -> 810
A5: =UPPER('route plans'!A57) -> 3 STAR HARDWARE BUILDING MATERIAL | B5: =UPPER('route plans'!B57) -> RELETO SECTION | C5: =UPPER('route plans'!C57) -> SILVERKRANS | D5: =UPPER('route plans'!D57) -> NORTH WEST | E5: =UPPER('route plans'!E57) -> 1435 RALETO SECTION, SILVERKRANS, NORTH WEST | F5: =UPPER('route plans'!G57) -> NO | G5: =UPPER('route plans'!H57) -> EST | L5: HARDWARE | M5: =UPPER('route plans'!N57) -> N/A | N5: =UPPER('route plans'!O57) -> NO | S5: =UPPER('route plans'!T57) -> M.W. ARSHAD | T5: ='route plans'!U57 -> 074 518 2972 | W5: ='route plans'!X57 -> 0 | X5: ='route plans'!Y57 -> 0 | Y5: =UPPER('route plans'!Z57) | Z5: =UPPER('route plans'!AA57) -> ALI.KHATANA07@GMAIL.COM | AB5: ='route plans'!AC57 -> 810
A6: =UPPER('route plans'!A535) -> 31 HARDWARE (PTY) LTD | B6: =UPPER('route plans'!B535) -> GEORGE | C6: =UPPER('route plans'!C535) -> GEORGE | D6: =UPPER('route plans'!D535) -> WESTERN CAPE | E6: =UPPER('route plans'!E535) -> DENNE OORD GEORGE 6529 | F6: =UPPER('route plans'!G535) -> NO | G6: =UPPER('route plans'!H535) -> EST | L6: HARDWARE | M6: =UPPER('route plans'!N535) -> N/A | N6: =UPPER('route plans'!O535) -> NO | S6: =UPPER('route plans'!T535) -> ELIZMA JOUBERT | T6: ='route plans'!U535 -> 044 050 3700 | W6: ='route plans'!X535 -> 0 | X6: ='route plans'!Y535 -> 0 | Y6: =UPPER('route plans'!Z535) | Z6: =UPPER('route plans'!AA535) | AB6: ='route plans'!AC535 -> #VALUE!
A7: =UPPER('route plans'!A732) -> 786 DIRECTION | B7: =UPPER('route plans'!B732) -> PALAPYE | C7: =UPPER('route plans'!C732) -> PALAPYE | D7: =UPPER('route plans'!D732) -> BOTSWANA | E7: =UPPER('route plans'!E732) -> BOPEDI WARD RAMOKGUNAMI VILLAGE CENTRAL DISTRICT BOTSWANA | F7: =UPPER('route plans'!G732) -> NO | G7: =UPPER('route plans'!H732) -> EST | L7: HARDWARE | M7: =UPPER('route plans'!N732) -> N/A | N7: =UPPER('route plans'!O732) -> NO | S7: =UPPER('route plans'!T732) -> FAROUK | T7: ='route plans'!U732 -> (267) 4922560 | W7: ='route plans'!X732 -> 0 | X7: ='route plans'!Y732 -> 0 | Y7: =UPPER('route plans'!Z732) | Z7: =UPPER('route plans'!AA732) -> TAWAQAL_INVESTMENT@YAHOO.COM;KHALIDPATEL37@YAHOO.COM | AB7: ='route plans'!AC732 -> #VALUE!
A8: =UPPER('route plans'!A2214) -> A H MARAIS SEUNS (EDMS) BPK | B8: =UPPER('route plans'!B2214) -> WORCESTER | C8: =UPPER('route plans'!C2214) -> WORCESTER | D8: =UPPER('route plans'!D2214) -> WESTERN CAPE | E8: =UPPER('route plans'!E2214) -> 12 FIELD ST | F8: =UPPER('route plans'!G2214) -> NO | G8: =UPPER('route plans'!H2214) -> NONE | L8: HARDWARE | M8: =UPPER('route plans'!N2214) -> 30DAYS | N8: =UPPER('route plans'!O2214) -> NO | S8: =UPPER('route plans'!T2214) -> JANNIE | T8: ='route plans'!U2214 -> 0236263071 | W8: ='route plans'!X2214 -> 0 | X8: ='route plans'!Y2214 -> 0 | Y8: =UPPER('route plans'!Z2214) | Z8: =UPPER('route plans'!AA2214) -> CTERBLANCHE@TAGRI.CO.ZA | AB8: ='route plans'!AC2214 -> 823
A9: =UPPER('route plans'!A711) -> A HARDWARE ZANDSPRUIT | B9: =UPPER('route plans'!B711) -> ZANDSPRUIT | C9: =UPPER('route plans'!C711) -> ROODEPOORT | D9: =UPPER('route plans'!D711) -> GAUTENG | E9: =UPPER('route plans'!E711) -> 187 MARINA ROAD ZANDSPRUIT ROODEPOORT 2169 | F9: =UPPER('route plans'!G711) -> NO | G9: =UPPER('route plans'!H711) -> EST | L9: HARDWARE | M9: =UPPER('route plans'!N711) -> N/A | N9: =UPPER('route plans'!O711) -> NO | S9: =UPPER('route plans'!T711) -> HAMZA/ZYED/MOHAMED | T9: ='route plans'!U711 -> 011 419 3019 | W9: ='route plans'!X711 -> 0 | X9: ='route plans'!Y711 -> 0 | Y9: =UPPER('route plans'!Z711) | Z9: =UPPER('route plans'!AA711) -> AHARDWAREMOKALE@GMAIL.COM;ADMIN@AHARDWARE.CO.ZA | AB9: ='route plans'!AC711 -> #VALUE!
A10: A Hardware Zandspruit | B10: Roodepoort | C10: Roodepoort | D10: Gauteng | E10: 187 Marina Road Zandspruit Roodepoort 2169 | G10: EST | L10: HARDWARE | S10: Hamza/Zyed/Mohamed | T10: 011 419 3019 | Z10: ahardwaremokale@gmail.com;admin@ahardware.co.za
A11: =UPPER('route plans'!A710) -> A HARDWARE KAGISO | B11: =UPPER('route plans'!B710) -> KAGISO | C11: =UPPER('route plans'!C710) -> KRUGERSDORP | D11: =UPPER('route plans'!D710) -> GAUTENG | E11: =UPPER('route plans'!E710) -> 1997 THEMBA DRIVE KAGISO CENTRAL | F11: =UPPER('route plans'!G710) -> NO | G11: =UPPER('route plans'!H710) -> EST | L11: HARDWARE | M11: =UPPER('route plans'!N710) -> N/A | N11: =UPPER('route plans'!O710) -> NO | S11: =UPPER('route plans'!T710) -> HAMZA/ZYED/MOHAMED | T11: ='route plans'!U710 -> 011 419 3019 | W11: ='route plans'!X710 -> 0 | X11: ='route plans'!Y710 -> 0 | Y11: =UPPER('route plans'!Z710) | Z11: =UPPER('route plans'!AA710) -> AHARDWAREMOKALE@GMAIL.COM;ADMIN@AHARDWARE.CO.ZA | AB11: ='route plans'!AC710 -> #VALUE!
A12: A Hardware Kagiso | B12: Krugersdorp | C12: Krugersdorp | D12: Gauteng | E12: 1997 Themba Drive Kagiso Central | G12: EST | L12: HARDWARE | S12: Hamza/Zyed/Mohamed | T12: 011 419 3019 | Z12: ahardwaremokale@gmail.com;admin@ahardware.co.za
A13: =UPPER('route plans'!A709) -> A HARDWARE MOKALE | B13: =UPPER('route plans'!B709) -> MOKALE | C13: =UPPER('route plans'!C709) -> KRUGERSDORP | D13: =UPPER('route plans'!D709) -> GAUTENG | E13: =UPPER('route plans'!E709) -> 14611 MASEDI STR RIVERSIDE KAGISO KURGERSDORP | F13: =UPPER('route plans'!G709) -> NO | G13: =UPPER('route plans'!H709) -> EST | L13: HARDWARE | M13: =UPPER('route plans'!N709) -> N/A | N13: =UPPER('route plans'!O709) -> NO | S13: =UPPER('route plans'!T709) -> HAMZA/ZYED/MOHAMED | T13: ='route plans'!U709 -> 011 419 3019 | W13: ='route plans'!X709 -> 0 | X13: ='route plans'!Y709 -> 0 | Y13: =UPPER('route plans'!Z709) | Z13: =UPPER('route plans'!AA709) -> AHARDWAREMOKALE@GMAIL.COM;ADMIN@AHARDWARE.CO.ZA | AB13: ='route plans'!AC709 -> #VALUE!
A14: A Hardware Mokale | B14: Krugersdorp | C14: Krugersdorp | D14: Gauteng | E14: 14611 Masedi Str Riverside Kagiso Kurgersdorp | G14: EST | L14: HARDWARE | S14: Hamza/Zyed/Mohamed | T14: 011 419 3019 | Z14: ahardwaremokale@gmail.com;admin@ahardware.co.za
A15: =UPPER('route plans'!A1943) -> A HARDWARE ZANDSPRUIT | B15: =UPPER('route plans'!B1943) -> ROODEPOORT | C15: =UPPER('route plans'!C1943) -> ROODEPOORT | D15: =UPPER('route plans'!D1943) -> GAUTENG | E15: =UPPER('route plans'!E1943) -> 187 MARINA ROAD ZANDSPRUIT ROODEPOORT 2169 | F15: =UPPER('route plans'!G1943) -> NO | G15: =UPPER('route plans'!H1943) -> BUILD IT | L15: HARDWARE | M15: =UPPER('route plans'!N1943) -> N/A | N15: =UPPER('route plans'!O1943) -> N | S15: =UPPER('route plans'!T1943) -> HAMZA/ZYED/MOHAMED | T15: ='route plans'!U1943 -> 011 419 3019 | W15: ='route plans'!X1943 -> 0 | X15: ='route plans'!Y1943 -> 0 | Y15: =UPPER('route plans'!Z1943) | Z15: =UPPER('route plans'!AA1943) -> AHARDWAREMOKALE@GMAIL.COM;ADMIN@AHARDWARE.CO.ZA | AB15: ='route plans'!AC1943 -> 823
A16: =UPPER('route plans'!A651) -> A ONE HARDWARE STORE | B16: =UPPER('route plans'!B651) -> GRABOUW | C16: =UPPER('route plans'!C651) -> GRABOUW | D16: =UPPER('route plans'!D651) -> WESTERN CAPE | E16: =UPPER('route plans'!E651) -> 1507 VIOLA STREET | F16: =UPPER('route plans'!G651) -> NO | G16: =UPPER('route plans'!H651) -> NONE | L16: HARDWARE | M16: =UPPER('route plans'!N651) -> 30DAYS | N16: =UPPER('route plans'!O651) -> NO | S16: =UPPER('route plans'!T651) -> INAM | T16: ='route plans'!U651 -> 0670124496 | W16: ='route plans'!X651 -> 44434 | X16: ='route plans'!Y651 -> 55 | Y16: =UPPER('route plans'!Z651) | Z16: =UPPER('route plans'!AA651) | AB16: ='route plans'!AC651 -> 832
A17: =UPPER('route plans'!A139) -> A PLUS MARKETING PTY LTD T/A MICA LENASIA | B17: =UPPER('route plans'!B139) -> LENASIA | C17: =UPPER('route plans'!C139) -> LENASIA | D17: =UPPER('route plans'!D139) -> GAUTENG | E17: =UPPER('route plans'!E139) -> 4 MAIN LAWLET RD | F17: =UPPER('route plans'!G139) -> NO | G17: =UPPER('route plans'!H139) -> FBS | L17: HARDWARE | M17: =UPPER('route plans'!N139) -> 30DAYS | N17: =UPPER('route plans'!O139) -> YES | S17: =UPPER('route plans'!T139) -> CERWIN | T17: ='route plans'!U139 -> 0118520797 | W17: ='route plans'!X139 -> 44484 | X17: ='route plans'!Y139 -> 5 | Y17: =UPPER('route plans'!Z139) -> TYRONE | Z17: =UPPER('route plans'!AA139) -> CERWINM@MICARETAIL.CO.ZA | AB17: ='route plans'!AC139 -> 810
A18: =UPPER('route plans'!A27) -> A.A BUILDING MATERIAL LESOTHO | B18: =UPPER('route plans'!B27) -> LERIBE | C18: =UPPER('route plans'!C27) -> LERIBE | D18: =UPPER('route plans'!D27) -> LESOTHO | E18: =UPPER('route plans'!E27) -> AIRPORT ROAD LERIBE LESOTHO | F18: =UPPER('route plans'!G27) -> NO | G18: =UPPER('route plans'!H27) -> EST | L18: HARDWARE | M18: =UPPER('route plans'!N27) -> N/A | N18: =UPPER('route plans'!O27) -> NO | S18: =UPPER('route plans'!T27) -> HASSEN NOORMOHAMED | T18: ='route plans'!U27 -> 266 22400795 | W18: ='route plans'!X27 -> 0 | X18: ='route plans'!Y27 -> 0 | Y18: =UPPER('route plans'!Z27) | Z18: =UPPER('route plans'!AA27) -> IRSHU7860@HOTMAIL.COM | AB18: ='route plans'!AC27 -> 810
A19: =UPPER('route plans'!A59) -> A.A BUILDING MATERIAL LESOTHO | B19: =UPPER('route plans'!B59) -> LERIBE | C19: =UPPER('route plans'!C59) -> LERIBE | D19: =UPPER('route plans'!D59) -> LESOTHO | E19: =UPPER('route plans'!E59) -> AIRPORT ROAD LERIBE LESOTHO | F19: =UPPER('route plans'!G59) -> NO | G19: =UPPER('route plans'!H59) -> EST | L19: HARDWARE | M19: =UPPER('route plans'!N59) -> N/A | N19: =UPPER('route plans'!O59) -> NO | S19: =UPPER('route plans'!T59) -> HASSEN NOORMOHAMED | T19: ='route plans'!U59 -> 266 22400795 | W19: ='route plans'!X59 -> 0 | X19: ='route plans'!Y59 -> 0 | Y19: =UPPER('route plans'!Z59) | Z19: =UPPER('route plans'!AA59) -> IRSHU7860@HOTMAIL.COM | AB19: ='route plans'!AC59 -> 810
A20: =UPPER('route plans'!A2140) -> A.A BUILDING MATERIAL LESOTHO | B20: =UPPER('route plans'!B2140) -> LERIBE | C20: =UPPER('route plans'!C2140) -> LERIBE | D20: =UPPER('route plans'!D2140) -> LESOTHO | E20: =UPPER('route plans'!E2140) -> AIRPORT ROAD LERIBE LESOTHO | F20: =UPPER('route plans'!G2140) -> NO | G20: =UPPER('route plans'!H2140) -> BUILD IT | L20: HARDWARE | M20: =UPPER('route plans'!N2140) -> N/A | N20: =UPPER('route plans'!O2140) -> N | S20: =UPPER('route plans'!T2140) -> HASSEN NOORMOHAMED | T20: ='route plans'!U2140 -> 266 22400795 | W20: ='route plans'!X2140 -> 0 | X20: ='route plans'!Y2140 -> 0 | Y20: =UPPER('route plans'!Z2140) | Z20: =UPPER('route plans'!AA2140) -> IRSHU7860@HOTMAIL.COM | AB20: ='route plans'!AC2140 -> 823
A21: A.A Building Material LESOTHO | B21: Leribe | C21: Leribe | D21: Lesotho | E21: Airport Road Leribe Lesotho | G21: EST | L21: HARDWARE | S21: Hassen Noormohamed | T21: 266 22400795 | Z21: irshu7860@hotmail.com
A22: =UPPER('route plans'!A565) -> A.G. HARDWARE | B22: =UPPER('route plans'!B565) -> STANGER | C22: =UPPER('route plans'!C565) -> STANGER | D22: =UPPER('route plans'!D565) -> KWAZULU-NATAL | E22: =UPPER('route plans'!E565) -> SHOP 2, GROUND FLOOR, 22 KING SHAKA STREET, STANGER, KWAZULU-NATAL, 4450 | F22: =UPPER('route plans'!G565) -> NO | G22: =UPPER('route plans'!H565) -> POWER BUILD | L22: HARDWARE | M22: =UPPER('route plans'!N565) -> N/A | N22: =UPPER('route plans'!O565) -> NO | S22: =UPPER('route plans'!T565) -> RAWA BILAL | T22: ='route plans'!U565 -> 032 437 8194 | W22: ='route plans'!X565 -> 0 | X22: ='route plans'!Y565 -> 44489 | Y22: =UPPER('route plans'!Z565) | Z22: =UPPER('route plans'!AA565) -> ADMIN@ADILGENERALTRADERS.CO.ZA | AB22: ='route plans'!AC565 -> 827
A23: =UPPER('route plans'!A495) -> A.H MART | B23: =UPPER('route plans'!B495) -> QUMBU | C23: =UPPER('route plans'!C495) -> QUMBU | D23: =UPPER('route plans'!D495) -> EASTERN CAPE | E23: =UPPER('route plans'!E495) -> 146 OLD MAIN ROAD / STREET, QUMBU, EASTERN CAPE,5180 | F23: =UPPER('route plans'!G495) -> NO | G23: =UPPER('route plans'!H495) -> POWER BUILD | L23: HARDWARE | M23: =UPPER('route plans'!N495) -> N/A | N23: =UPPER('route plans'!O495) -> NO | S23: =UPPER('route plans'!T495) -> MUHAMMAD ASIF | T23: ='route plans'!U495 -> 073 993 9786 | W23: ='route plans'!X495 -> 0 | X23: ='route plans'!Y495 -> 44489 | Y23: =UPPER('route plans'!Z495) | Z23: =UPPER('route plans'!AA495) -> INFO@AHMART.CO.ZA | AB23: ='route plans'!AC495 -> 827
A24: =UPPER('route plans'!A496) -> A.H MART (ADDITIONAL DELIVERY ADDRESS MDANTSANE) | B24: =UPPER('route plans'!B496) -> MDANTSANE | C24: =UPPER('route plans'!C496) -> MDANTSANE | D24: =UPPER('route plans'!D496) -> EASTERN CAPE | E24: =UPPER('route plans'!E496) -> SHOP NO.8, SHOPRITE MALL, NU2 HIGHWAY, MDANTSANE, 5419 | F24: =UPPER('route plans'!G496) -> NO | G24: =UPPER('route plans'!H496) -> POWER BUILD | L24: HARDWARE | M24: =UPPER('route plans'!N496) -> N/A | N24: =UPPER('route plans'!O496) -> NO | S24: =UPPER('route plans'!T496) -> MUHAMMAD ASIF | T24: ='route plans'!U496 -> 073 993 9786 | W24: ='route plans'!X496 -> 0 | X24: ='route plans'!Y496 -> 44489 | Y24: =UPPER('route plans'!Z496) | Z24: =UPPER('route plans'!AA496) -> INFO@AHMART.CO.ZA | AB24: ='route plans'!AC496 -> 827
A25: =UPPER('route plans'!A497) -> A.H MART (ADDITIONAL DELIVERY ADDRESS QUEENSTOWN) | B25: =UPPER('route plans'!B497) -> QUEENSTOWN | C25: =UPPER('route plans'!C497) -> QUEENSTOWN | D25: =UPPER('route plans'!D497) -> EASTERN CAPE | E25: =UPPER('route plans'!E497) -> 6 SHEPSTONE STREET, QUEENSTOWN, EASTERN CAPE, 5320 | F25: =UPPER('route plans'!G497) -> NO | G25: =UPPER('route plans'!H497) -> POWER BUILD | L25: HARDWARE | M25: =UPPER('route plans'!N497) -> N/A | N25: =UPPER('route plans'!O497) -> NO | S25: =UPPER('route plans'!T497) -> MUHAMMAD ASIF | T25: ='route plans'!U497 -> 073 993 9786 | W25: ='route plans'!X497 -> 0 | X25: ='route plans'!Y497 -> 44489 | Y25: =UPPER('route plans'!Z497) | Z25: =UPPER('route plans'!AA497) -> INFO@AHMART.CO.ZA | AB25: ='route plans'!AC497 -> 827
A26: =UPPER('route plans'!A672) -> AB JAMIE TRADING | B26: =UPPER('route plans'!B672) -> COFIMVABA | C26: =UPPER('route plans'!C672) -> COFIMVABA | D26: =UPPER('route plans'!D672) -> EASTERN CAPE | E26: =UPPER('route plans'!E672) -> ERG 76 MAIN STREET COFIMVABA | F26: =UPPER('route plans'!G672) -> NO | G26: =UPPER('route plans'!H672) -> EST | L26: HARDWARE | M26: =UPPER('route plans'!N672) -> N/A | N26: =UPPER('route plans'!O672) -> NO | S26: =UPPER('route plans'!T672) -> ERF 76 MAIN STREET COFIMVABA | T26: ='route plans'!U672 -> 047 874 0810 | W26: ='route plans'!X672 -> 0 | X26: ='route plans'!Y672 -> 0 | Y26: =UPPER('route plans'!Z672) | Z26: =UPPER('route plans'!AA672) -> KINGHARDWARE003@GMAIL.COM | AB26: ='route plans'!AC672 -> #VALUE!
A27: =UPPER('route plans'!A564) -> ABBA MOOSA HARDWARE | B27: =UPPER('route plans'!B564) -> OVERPORT | C27: =UPPER('route plans'!C564) -> OVERPORT | D27: =UPPER('route plans'!D564) -> KWAZULU-NATAL | E27: =UPPER('route plans'!E564) -> 189 MOSES KOTANE ROAD, OVERPORT, 4091 | F27: =UPPER('route plans'!G564) -> NO | G27: =UPPER('route plans'!H564) -> POWER BUILD | L27: HARDWARE | M27: =UPPER('route plans'!N564) -> N/A | N27: =UPPER('route plans'!O564) -> NO | S27: =UPPER('route plans'!T564) -> ZAHEER ESSA | T27: ='route plans'!U564 -> 031 208 6511 | W27: ='route plans'!X564 -> 0 | X27: ='route plans'!Y564 -> 44489 | Y27: =UPPER('route plans'!Z564) | Z27: =UPPER('route plans'!AA564) -> ABBAMOOSAS@GMAIL.COM | AB27: ='route plans'!AC564 -> 827
A28: =UPPER('route plans'!A2124) -> ABERDARE HARDWARE | B28: =UPPER('route plans'!B2124) -> PHOENIX | C28: =UPPER('route plans'!C2124) -> PHOENIX | D28: =UPPER('route plans'!D2124) -> KWAZULU-NATAL | E28: =UPPER('route plans'!E2124) -> 261 ABERDARE DR PHOENIX INDUSTRIAL PARK 4068 | F28: =UPPER('route plans'!G2124) -> NO | G28: =UPPER('route plans'!H2124) -> BUILD IT | L28: HARDWARE | M28: =UPPER('route plans'!N2124) -> N/A | N28: =UPPER('route plans'!O2124) -> N | S28: =UPPER('route plans'!T2124) -> MR D MAHARAJ | T28: ='route plans'!U2124 -> 031 500 5306 | W28: ='route plans'!X2124 -> 0 | X28: ='route plans'!Y2124 -> 0 | Y28: =UPPER('route plans'!Z2124) | Z28: =UPPER('route plans'!AA2124) -> MAHOMED.HASSIM@PINETIMBERS.CO.ZA | AB28: ='route plans'!AC2124 -> 823
A29: =UPPER('route plans'!A671) -> ABERDARE HARDWARE | B29: =UPPER('route plans'!B671) -> PHOENIX | C29: =UPPER('route plans'!C671) -> PHOENIX | D29: =UPPER('route plans'!D671) -> KWAZULU-NATAL | E29: =UPPER('route plans'!E671) -> 261 ABERDARE DR PHOENIX INDUSTRIAL PARK 4068 | F29: =UPPER('route plans'!G671) -> NO | G29: =UPPER('route plans'!H671) -> EST | L29: HARDWARE | M29: =UPPER('route plans'!N671) -> N/A | N29: =UPPER('route plans'!O671) -> NO | S29: =UPPER('route plans'!T671) -> MR D MAHARAJ | T29: ='route plans'!U671 -> 031 500 5306 | W29: ='route plans'!X671 -> 0 | X29: ='route plans'!Y671 -> 0 | Y29: =UPPER('route plans'!Z671) | Z29: =UPPER('route plans'!AA671) -> ABEDARE@TELKOMSA.NET;LEAESH@ABERDARE.BIZ | AB29: ='route plans'!AC671 -> #VALUE!
A30: Aberdare Hardware | B30: Phoenix | C30: Phoenix | D30: KwaZulu-Natal | E30: 261 Aberdare Dr Phoenix Industrial Park 4068 | G30: EST | L30: HARDWARE | S30: Mr D Maharaj | T30: 031 500 5306 | Z30: abedare@telkomsa.net
A31: =UPPER('route plans'!A2224) -> ABM PLUMBING & ELECTRICAL | B31: =UPPER('route plans'!B2224) -> WYNBERG | C31: =UPPER('route plans'!C2224) -> WYNBERG | D31: =UPPER('route plans'!D2224) -> WESTERN CAPE | E31: =UPPER('route plans'!E2224) -> 1 OTTERY RD | F31: =UPPER('route plans'!G2224) -> NO | G31: =UPPER('route plans'!H2224) -> NONE | L31: HARDWARE | M31: =UPPER('route plans'!N2224) -> 30DAYS | N31: =UPPER('route plans'!O2224) -> NO | S31: =UPPER('route plans'!T2224) -> NYTAN | T31: ='route plans'!U2224 -> #N/A | W31: ='route plans'!X2224 -> 0 | X31: ='route plans'!Y2224 -> 0 | Y31: =UPPER('route plans'!Z2224) | Z31: =UPPER('route plans'!AA2224) -> SIEGFRIED@BENBEL.CO.ZA | AB31: ='route plans'!AC2224 -> 823
A32: =UPPER('route plans'!A673) -> ABOO HARDWARE STEILOOP | B32: =UPPER('route plans'!B673) -> STEILOOP | C32: =UPPER('route plans'!C673) -> MOKOPANE | D32: =UPPER('route plans'!D673) -> LIMPOPO | E32: =UPPER('route plans'!E673) -> NO 27 STEILOOP COMPLEX N11 | F32: =UPPER('route plans'!G673) -> NO | G32: =UPPER('route plans'!H673) -> EST | L32: HARDWARE | M32: =UPPER('route plans'!N673) -> N/A | N32: =UPPER('route plans'!O673) -> NO | S32: =UPPER('route plans'!T673) -> MOHAMED | T32: ='route plans'!U673 -> 078 237 8828 | W32: ='route plans'!X673 -> 0 | X32: ='route plans'!Y673 -> 0 | Y32: =UPPER('route plans'!Z673) | Z32: =UPPER('route plans'!AA673) -> ABOO@TAAHAA.CO.ZA | AB32: ='route plans'!AC673 -> #VALUE!
A33: Aboo Hardware Steiloop | B33: Mokopane | C33: Mokopane | D33: Limpopo | E33: No 27 Steiloop Complex N11 | G33: EST | L33: HARDWARE | S33: Mohamed | T33: 078 237 8828 | Z33: aboo@taahaa.co.za
A34: =UPPER('route plans'!A674) -> ACE HARDWARE | B34: =UPPER('route plans'!B674) -> BURGERSFORT | C34: =UPPER('route plans'!C674) -> BURGERSFORT | D34: =UPPER('route plans'!D674) -> LIMPOPO | E34: =UPPER('route plans'!E674) -> 8 TARFAN PLAZA, MAIN RD, BURGERSFORT | F34: =UPPER('route plans'!G674) -> NO | G34: =UPPER('route plans'!H674) -> EST | L34: HARDWARE | M34: =UPPER('route plans'!N674) -> N/A | N34: =UPPER('route plans'!O674) -> NO | S34: =UPPER('route plans'!T674) -> TAR MAHOMED | T34: ='route plans'!U674 -> 013 231 7861 | W34: ='route plans'!X674 -> 0 | X34: ='route plans'!Y674 -> 0 | Y34: =UPPER('route plans'!Z674) | Z34: =UPPER('route plans'!AA674) -> ABU@ACEHARDWARE.CO.ZA | AB34: ='route plans'!AC674 -> #VALUE!
A35: Ace Hardware | B35: Burgersfort | C35: Burgersfort | D35: Limpopo | E35: 8 Tarfan Plaza, Main Rd, Burgersfort | G35: EST | L35: HARDWARE | S35: Tar Mahomed | T35: 013 231 7861 | Z35: abu@acehardware.co.za
A36: Ace Hardware & Furnishers Standerton | B36: Standerton | C36: Standerton | D36: Mpumalanga | E36: Shop 44 Oriental Plaza Standerton 2430 | G36: EST | L36: HARDWARE | S36: Naeem Gani | T36: 017 712 5891 | Z36: hardewareace40@gmail.com
A37: =UPPER('route plans'!A2150) -> ACE TILE & PAINT HARDWARE | B37: =UPPER('route plans'!B2150) -> PHOENIX | C37: =UPPER('route plans'!C2150) -> PHOENIX | D37: =UPPER('route plans'!D2150) -> KWAZULU-NATAL | E37: =UPPER('route plans'!E2150) -> 273 ABERDARE DRIVE, PHOENIX | F37: =UPPER('route plans'!G2150) -> NO | G37: =UPPER('route plans'!H2150) -> BUILD IT | L37: HARDWARE | M37: =UPPER('route plans'!N2150) -> N/A | N37: =UPPER('route plans'!O2150) -> N | S37: =UPPER('route plans'!T2150) -> AMID AKONJEE | T37: ='route plans'!U2150 -> 031 507 1214 | W37: ='route plans'!X2150 -> 0 | X37: ='route plans'!Y2150 -> 0 | Y37: =UPPER('route plans'!Z2150) | Z37: =UPPER('route plans'!AA2150) -> ABEDARE@TELKOMSA.NET | AB37: ='route plans'!AC2150 -> 823
A38: =UPPER('route plans'!A676) -> ACE TILE & PAINT HARDWARE | B38: =UPPER('route plans'!B676) -> PHOENIX | C38: =UPPER('route plans'!C676) -> PHOENIX | D38: =UPPER('route plans'!D676) -> KWAZULU-NATAL | E38: =UPPER('route plans'!E676) -> 273 ABERDARE DRIVE, PHOENIX | F38: =UPPER('route plans'!G676) -> NO | G38: =UPPER('route plans'!H676) -> EST | L38: HARDWARE | M38: =UPPER('route plans'!N676) -> N/A | N38: =UPPER('route plans'!O676) -> NO | S38: =UPPER('route plans'!T676) -> AMID AKONJEE | T38: ='route plans'!U676 -> 031 507 1214 | W38: ='route plans'!X676 -> 0 | X38: ='route plans'!Y676 -> 0 | Y38: =UPPER('route plans'!Z676) | Z38: =UPPER('route plans'!AA676) -> ACETILES@TELKOMSA.NET | AB38: ='route plans'!AC676 -> #VALUE!
A39: Ace Tile & paint Hardware | B39: Phoenix | C39: Phoenix | D39: KwaZulu-Natal | E39: 273 Aberdare Drive, Phoenix | G39: EST | L39: HARDWARE | S39: Amid Akonjee | T39: 031 507 1214 | Z39: acetiles@telkomsa.net
A40: Acornhoek Hardware | B40: Acornhoek | C40: Acornhoek | D40: Mpumalanga | E40: Shop 8 Acornhoek Mega City Acornhoek 1360 | G40: EST | L40: HARDWARE | S40: Abdul Munaf Turk | T40: 013 795 5680 | Z40: mafio@hotmail.co.za
...

Sheet Sheet2
A1: BEST HARDWARE | B1: KWAMHLANGA | C1: KWAMHLANGA | D1: MPUMALANGA | E1: SHELDON ROAD, KWAMHALANGA | F1: BEST HARDWARE | G1: KWAMHLANGA | H1: KWAMHLANGA | I1: MPUMALANGA | J1: SHELDON ROAD, KWAMHALANGA
A2: RAJA HARDWARE KWAMHLANGA | B2: KWAMHLANGA | C2: KWAMHLANGA | D2: MPUMALANGA | E2: 1891/2, KWAMHLANGA, 1022 | F2: RAJA HARDWARE KWAMHLANGA | G2: KWAMHLANGA | H2: KWAMHLANGA | I2: MPUMALANGA | J2: 1891/2, KWAMHLANGA, 1022
A3: SA HARDWARE | B3: KWAMHLANGA | C3: KWAMHLANGA | D3: MPUMALANGA | E3: KWAMHLANGA | F3: SA HARDWARE | G3: KWAMHLANGA | H3: KWAMHLANGA | I3: MPUMALANGA | J3: KWAMHLANGA
A4: SUNNY'S HARDWARE KWAMHLANGA | B4: KWAMHLANGA | C4: KWAMHLANGA | D4: MPUMALANGA | E4: 7777 MOLOTO ROAD, KWAMHLANGA | F4: SUNNY'S HARDWARE KWAMHLANGA | G4: KWAMHLANGA | H4: KWAMHLANGA | I4: MPUMALANGA | J4: 7777 MOLOTO ROAD, KWAMHLANGA
A5: SUNNYS HARDWARE SHOP 2 | B5: KWAMHLANGA | C5: KWAMHLANGA | D5: MPUMALANGA | E5: TWEEFONTEIN G R573 KWAMHLANGA | F5: SUNNYS HARDWARE SHOP 2 | G5: KWAMHLANGA | H5: KWAMHLANGA | I5: MPUMALANGA | J5: TWEEFONTEIN G R573 KWAMHLANGA
A6: SHIDY'S HARWARE | B6: KWAMHLANGA | C6: KWAMHLANGA | D6: MPUMALANGA | E6: KWAMHLANGA | F6: SHIDY'S HARWARE | G6: KWAMHLANGA | H6: KWAMHLANGA | I6: MPUMALANGA | J6: KWAMHLANGA
A7: PHOLA HARDWARE & TILE | B7: KWAMHLANGA | C7: KWAMHLANGA | D7: MPUMALANGA | E7: 3,4,5 PHOLA PARK, KWAMHLANGA CROSS ROAD, KWAMHLANGA | F7: PHOLA HARDWARE & TILE | G7: KWAMHLANGA | H7: KWAMHLANGA | I7: MPUMALANGA | J7: 3,4,5 PHOLA PARK, KWAMHLANGA CROSS ROAD, KWAMHLANGA
A8: PHOOL HARDWARE | B8: KWAMHLANGA | C8: KWAMHLANGA | D8: MPUMALANGA | E8: 7936 LETHULI SECTION | F8: PHOOL HARDWARE | G8: KWAMHLANGA | H8: KWAMHLANGA | I8: MPUMALANGA | J8: 7936 LETHULI SECTION
A9: QISMAT HARDWARE | B9: KWAMHLANGA | C9: KWAMHLANGA | D9: MPUMALANGA | E9: SHELDON ROAD, KHAYALISHA | F9: QISMAT HARDWARE | G9: KWAMHLANGA | H9: KWAMHLANGA | I9: MPUMALANGA | J9: SHELDON ROAD, KHAYALISHA
A10: MJ HARDWARE | B10: KWAMHLANGA | C10: KWAMHLANGA | D10: MPUMALANGA | E10: 1891 TWEEFONTEIN, KWAMHLANGA | F10: MJ HARDWARE | G10: KWAMHLANGA | H10: KWAMHLANGA | I10: MPUMALANGA | J10: 1891 TWEEFONTEIN, KWAMHLANGA

Sheet Sheet3
A1: PWR BUILD (PTY) LTD MONTHLY SALES TRACKER - SUPPLIER FIGURES 2022
A2: SUPPLIER NAME: INSERT NAME HERE | F2: Ver 36- 1 June 22 | U2: 2022
A3: POWER BUILD MEMBERS
A4: Region | B4: Account Number | C4: Legal Entity | D4: Trading Name | E4: Physical Address | F4: Vat Number | G4: Date Joined | H4: Supp Member account no | I4: 44562 | J4: 44593 | K4: 44621 | L4: 44652 | M4: 44682 | N4: 44713 | O4: 44743 | P4: 44774 | Q4: 44805 | R4: 44835 | S4: 44866 | T4: 44896 | U4: TOTAL 2019/2020
A5: Botswana | B5: MAXIS0003 | C5: Maxi Save Botswana (Pty) Ltd | D5: Maxi Save | E5: Plot 22015, Gaborone West, Gaborone | F5: C00771501112 | G5: 1 Feb 20 | U5: =SUM(I5:T5) -> 0
A6: Eastern Cape | B6: AHMAQECRB3 | C6: A.H. Mart (Pty) Ltd | D6: A.H Mart | E6: 146 Old Main Road / Street, Qumbu, Eastern Cape,5180 | F6: 4300286764 | G6: 4-Aug-20 | U6: =SUM(I6:T6) -> 0
A7: Eastern Cape | B7: AHMAMECRB3 | C7: A.H. Mart (Pty) Ltd | D7: A.H Mart (Additional Delivery Address Mdantsane) | E7: Shop No.8, Shoprite Mall, NU2 Highway, Mdantsane, 5419 | F7: 4300286764 | G7: 4-Aug-20 | U7: =SUM(I7:T7) -> 0
A8: Eastern Cape | B8: AHMA2ECUB3 | C8: A.H. Mart (Pty) Ltd | D8: A.H Mart (Additional Delivery Address Queenstown) | E8: 6 Shepstone Street, Queenstown, Eastern Cape, 5320 | F8: 4300286764 | G8: 44328 | U8: =SUM(I8:T8) -> 0
A9: Eastern Cape | B9: MASAKECRB6 | C9: Ali Vision Trading (Pty) Ltd | D9: Masakhane Hardware | E9: Shop No 2, Maint Street, Viedgesville | F9: TBA | G9: 44317 | U9: =SUM(I9:T9) -> 0
A10: Eastern Cape | B10: BUMK1ECSD5 | C10: Build Mart Holdings (Pty) Ltd | D10: Build Mart | E10: 21 Groom Street, Kokstad, 4700 | F10: Pending | G10: 43770 | U10: =SUM(I10:T10) -> 0
A11: Eastern Cape | B11: CITYMECRB6 | C11: City Hardware Matatiele (Pty) Ltd | D11: City Hardware Matatiele | E11: 17 Long Street, Matatiele, eastern Cape, 4730 | F11: 4950280547 | G11: 44440 | U11: =SUM(I11:T11) -> 0
A12: Eastern Cape | B12: HOMEDECUB4 | C12: Come To Trade Hardware (Pty) Ltd | D12: Home Depo | E12: No 2 Blyth Street, Butterworth, 4960 | F12: Pending | G12: 43678 | U12: =SUM(I12:T12) -> 0
A13: Eastern Cape | B13: AFRIAECRB5 | C13: Frands Tranding and Projects 4 CC | D13: Africa Hardware | E13: Erf 21, Main Street, Mqanduli, 5080 | F13: 4220253084 | G13: 43990 | U13: =SUM(I13:T13) -> 0
A14: Eastern Cape | B14: ENKIHECRB5 | C14: Frands Tranding and Projects 4 CC | D14: Enkosi Hardware | E14: Erf 24, Main Street, Mqanduli, 5080 | F14: 4220253084 | G14: 43990 | U14: =SUM(I14:T14) -> 0
A15: Eastern Cape | B15: GAZI2ECUB5 | C15: Good Luck Hardware (Pty) Ltd | D15: Gazi Hardware | E15: 55 Main Street, Dordrect, Eastern Cape, 5470 | F15: TBA | G15: 44334 | U15: =SUM(I15:T15) -> 0
A16: Eastern Cape | B16: GOOD1ECUB5 | C16: Good Luck Hardware (Pty) Ltd | D16: Good Luck Hardware Ugie | E16: 12 Plein Street, Ugie, Eastern Cape, 5470 | F16: TBA | G16: 44334 | U16: =SUM(I16:T16) -> 0
A17: Eastern Cape | B17: EHDI1ECUD6 | C17: Happy Home Investments (Pty) Ltd | D17: Eyethu Hardware DIY Fort Beaufort | E17: 60 Campbell Street, Fort Beaufort, Eastern Cape, 5720 | F17: Pending | G17: 44470 | U17: =SUM(I17:T17) -> 0
A18: Eastern Cape | B18: ENDI2ECUD6 | C18: Happy Home Investments (Pty) Ltd | D18: Eyethu Hardware DIY Fort Beaufort (Barrack Street) | E18: 42 Barrack Street, Fort Beaufort, 5720 | F18: Pending | G18: 44470 | U18: =SUM(I18:T18) -> 0
A19: Eastern Cape | B19: ENDI3ECUD6 | C19: Happy Home Investments (Pty) Ltd | D19: Eyethu Hardware DIY Fort Beaufort (StringFellow Street) | E19: 17 Stringfellow Street, Adelaide, 5760 | F19: Pending | G19: 44470 | U19: =SUM(I19:T19) -> 0
A20: Eastern Cape | B20: BLOCCECRB6 | C20: High Class Trading and Construction (Pty) Ltd | D20: Block City | E20: 1069 Braodsword Road, Zitulele Industrial Butterworth, Eastern Cape, 4960 | F20: Pending | G20: 44470 | U20: =SUM(I20:T20) -> 0
A21: Eastern Cape | B21: AKHDWECRD6 | C21: Inter Kei Investments | D21: AK Hardwrae | E21: 82 Thurston Street, Tsolo, South Africa, 5170 | F21: 4810288623 | G21: 44448 | U21: =SUM(I21:T21) -> 0
A22: Eastern Cape | B22: BCSHHECRB6 | C22: Izam Trading (Pty) Ltd | D22: Build Cash Hardware | E22: N2 Ultra City, East London Road, Umtata, 5100 | F22: Pending | G22: 43990 | U22: =SUM(I22:T22) -> 0
A23: Eastern Cape | B23: KHAWHECRB3 | C23: Khawer (Pty) Ltd | D23: Khawer Hardware | E23: 62 North Street, Qumbu, 5180 | F23: 4430290702 | G23: 11 Nov 20 | U23: =SUM(I23:T23) -> 0
A24: Eastern Cape | B24: BUFFMECRB6 | C24: Lala Hardware (Pty) Ltd | D24: Buffalo Hardware | E24: Shop 1, Albert Street, Peddie, Eastern Cape, 5640 | F24: 9092299230 | G24: 44621 | U24: =SUM(I24:T24) -> 0
A25: Eastern Cape | B25: LALAHECRB6 | C25: Lala Hardware (Pty) Ltd | D25: Lala Hardware | E25: Shop 3, Albert Street, Peddie, Eastern Cape, 5640 | F25: 9092299230 | G25: 44621 | U25: =SUM(I25:T25) -> 0
A26: Eastern Cape | B26: INDALECSB4 | C26: Major Asjad Traders (Pty) Ltd | D26: Allied Build (Additional Delivery Address for Indali) | E26: 15 Errol Spring Avenue, Vulindlela Heights, Mthatha, 5099 | F26: 4240263055 | G26: 43850 | U26: =SUM(I26:T26) -> 0
A27: Eastern Cape | B27: IDDBSECUB4 | C27: Major Asjad Traders (Pty) Ltd | D27: Indali Building Supplier | E27: R61, Port St Johns Road, Coana ,Mthatha ,5099 | F27: 4240263055 | G27: 43850 | U27: =SUM(I27:T27) -> 0
A28: Eastern Cape | B28: LURHHECUB4 | C28: Major Asjad Traders (Pty) Ltd | D28: Lurhasini Hardware (Additional Delivery Address for Indali) | E28: N2 Road Lurhasini, Mthatha, 5116 | F28: 4240263055 | G28: 43850 | U28: =SUM(I28:T28) -> 0
A29: Eastern Cape | B29: MHENGECRB6 | C29: Mfundisi Bricks & Hardware (Pty) Ltd | D29: Mfundisi Hardware Engcobo | E29: 205 Main Street, Ngcobo, Eastern Cape, 5050 | F29: 4370283386 | G29: 44470 | U29: =SUM(I29:T29) -> 0
A30: Eastern Cape | B30: BFALIECSB5 | C30: Modern Time Trading CC | D30: Ali's Hardware (Additional Delivery Address for Buildfast) | E30: 6 Ntsizwa Street, Mt Ayliff, Eastern Cape, 4735 | F30: 40702585555 | G30: 43739 | U30: =SUM(I30:T30) -> 0
A31: Eastern Cape | B31: BUFT1ECSB5 | C31: Modern Time Trading CC | D31: Buildfast Warehouse | E31: Shop 15 to 20, Ntsizwa Street, Mt Ayliff, Eastern Cape, 4735 | F31: 40702585555 | G31: 43739 | U31: =SUM(I31:T31) -> 0
A32: Eastern Cape | B32: KINGNECRB3 | C32: Namul Trading (Pty) Ltd | D32: Kings Hardware (Maclear) | E32: Shop No 2, Fourie Street, Maclear, 5480 | F32: 4380286833 | G32: 44146 | U32: =SUM(I32:T32) -> 0
A33: Eastern Cape | B33: HARDWECRB5 | C33: Nedtex 4 CC | D33: Hardware Citi Sterkspruit | E33: 1 Van Tonder Street, Sterkspruit, Eastern Cape | F33: 4650257407 | G33: 44385 | U33: =SUM(I33:T33) -> 0
A34: Eastern Cape | B34: WELCOECRB5 | C34: Phindabantu Services (Pty) Ltd | D34: Welcome Hardware | E34: R61 Main Engcobo Road, Coghlan, Eastern Cape, 5054 | F34: 4270292693 | G34: 44334 | U34: =SUM(I34:T34) -> 0
A35: Eastern Cape | B35: RAJA1ECUB5 | C35: Raja Electronic Shop CC | D35: Raja Hardware Shop 1 | E35: 9 Gilwell Street, East London, 5209 | F35: 42302550238 | G35: 44105 | U35: =SUM(I35:T35) -> 0
A36: Eastern Cape | B36: RAJA2ECUB5 | C36: Raja Electronic Shop CC | D36: Raja Hardware Shop 2 | E36: Shop 1, Main Street N2, Opposite KFC Idutywa | F36: 42302550238 | G36: 44105 | U36: =SUM(I36:T36) -> 0
A37: Eastern Cape | B37: OSSKWECRB6 | C37: S.H. Rizvi T/A Ossher Bros | D37: Ossher Bros | E37: No. 2341 Main Dimbaza Road, Thembisa Ext, Near King Williams Town, 5671 | F37: Pending | G37: 44470 | U37: =SUM(I37:T37) -> 0
